Workbook
Name 관통슬리브: #REF!
Name 벽체_강관: #REF!
Name 벽체_강관_100A: #REF!
Name 벽체_강관_125A: #REF!
Name 벽체_강관_150A: #REF!
Name 벽체_강관_15A: #REF!
Name 벽체_강관_200A: #REF!
Name 벽체_강관_20A: #REF!
Name 벽체_강관_25A: #REF!
Name 벽체_강관_32A: #REF!
Name 벽체_강관_40A: #REF!
Name 벽체_강관_50A: #REF!
Name 벽체_강관_65A: #REF!
Name 벽체_강관_80A: #REF!
Name 벽체_PVC: #REF!
Name 벽체_PVC_100A: #REF!
Name 벽체_PVC_125A: #REF!
Name 벽체_PVC_150A: #REF!
Name 벽체_PVC_25A: #REF!
Name 벽체_PVC_30A: #REF!
Name 벽체_PVC_35A: #REF!
Name 벽체_PVC_40A: #REF!
Name 벽체_PVC_50A: #REF!
Name 벽체_PVC_65A: #REF!
Name 벽체_PVC_75A: #REF!
Name 벽체_SU: #REF!
Name 벽체_SU_100A: #REF!
Name 벽체_SU_20A: #REF!
Name 벽체_SU_25A: #REF!
Name 벽체_SU_30A: #REF!
Name 벽체_SU_40A: #REF!
Name 벽체_SU_50A: #REF!
Name 벽체_SU_60A: #REF!
Name 벽체_SU_75A: #REF!
Name 벽체_SU_80A: #REF!
Name 연장관: #REF!
Name 오배수_섹스티아: #REF!
Name 원형댐퍼: #REF!
Name 원형덕트: #REF!
Name 입상_강관_고정구_일체형: #REF!
Name 입상_강관_고정구_일체형_100A: #REF!
Name 입상_강관_고정구_일체형_15A: #REF!
Name 입상_강관_고정구_일체형_20A: #REF!
Name 입상_강관_고정구_일체형_25A: #REF!
Name 입상_강관_고정구_일체형_32A: #REF!
Name 입상_강관_고정구_일체형_40A: #REF!
Name 입상_강관_고정구_일체형_50A: #REF!
Name 입상_강관_고정구_일체형_65A: #REF!
Name 입상_강관_고정구_일체형_80A: #REF!
Name 입상_강관_고정구_일체형_ABS: #REF!
Name 입상_강관_고정틀: #REF!+#REF!
Name 입상_강관_고정틀_100A: #REF!
Name 입상_강관_고정틀_125A: #REF!
Name 입상_강관_고정틀_150A: #REF!
Name 입상_강관_고정틀_15A: #REF!
Name 입상_강관_고정틀_20A: #REF!
Name 입상_강관_고정틀_25A: #REF!
Name 입상_강관_고정틀_32A: #REF!
Name 입상_강관_고정틀_40A: #REF!
Name 입상_강관_고정틀_50A: #REF!

Sheet 1.발주접수
B4: 발주접수 | F4: 발주의뢰
B5: 발주의뢰처 | C5: 예시용 | F5: 발주수신처 | G5: 필립산업
B6: 발주접수 | C6: 46058
B7: 납품희망일 | C7: 46072
B8: 현장명 | C8: 현장명 예시
B9: 납 품 장 소 | C9: 남품장소 예시
B10: 주 소 | C10: 주소 예시
B11: 인수자 | C11: 인수자 예시
B12: 인수자 연락처 | C12: 연락처 예시
B13: 현장요청사항 | C13: 요청사항 예시
B14: 납품처 | C14: 납품처 예시
B17: NOTE
B18: 발주 후
B19: 1. 수주현황 에 입력
B20: 2. 프로화이어에 접수 유무를 확인
B21: 3. 거래처에 접수 현황 알림

Sheet 2.고정구단가산출
B2: 초록색 부분은 단가표 검색을 위한 부분입니다. 드롭다운으로 구성되어 있습니다. 1. 품명에 맞게 드롭다운에서 선택을 합니다. | F2: 연한 노란색 부분은 수기로 입력 바랍니다.
F5: 연한 주황색 부분은 자동 산출 됩니다.
B8: 제조사 | C8: 필립산업 | F8: =#REF! -> #REF!
B11: 고정구 견적서 단가 산출
C12: 검색 품명 | D12: 배관 | E12: 슬리브 | F12: 견적서 품명 | G12: 규격 | H12: 단위 | I12: 수량 | J12: 적요 | K12: 비고 | L12: 차열재 길이 | M12: 차열재 개수 | N12: 차열재 가격 | O12: 총 차열재 길이 | P12: 차열재 품목 | Q12: 실란트 용량 | R12: 실란트 가격 | S12: 총 실란트 | T12: 단가 | U12: 일위대가표 | V12: 판매가 | W12: 단가 기준 금액 | X12: 일위대가표 금액 | Y12: 금액
B13: 1 | C13: 벽체_강관 | D13: 벽체_강관_15A | E13: 50A | F13: 내화채움구조(벽체,강관용) | G13: 15*25 | H13: 개소 | I13: 3 | K13: =IF(V13=0, "판매가 없음", _xlfn.XLOOKUP( C13 & "|" & D13 & "|" & E13,#REF!,#REF!, "0" ) ) -> #REF! | L13: =_xlfn.XLOOKUP( C13 & "|" & D13 & "|" & E13,#REF!,#REF!, 0 ) -> #REF! | M13: =_xlfn.XLOOKUP( C13 & "|" & D13 & "|" & E13,#REF!,#REF!, 0 ) -> #REF! | N13: =_xlfn.XLOOKUP( C13 & "|" & D13 & "|" & E13,#REF!,#REF!, 0 ) -> #REF! | O13: =L13*I13 -> #REF! | P13: =_xlfn.XLOOKUP( C13 & "|" & D13 & "|" & E13,#REF!,#REF!, "차열재 없음" ) -> #REF! | Q13: =_xlfn.XLOOKUP( C13 & "|" & D13 & "|" & E13,#REF!,#REF!, "0" ) -> #REF! | R13: =_xlfn.XLOOKUP( C13 & "|" & D13 & "|" & E13,#REF!,#REF!, "0" ) -> #REF! | S13: =Q13*I13 -> #REF! | T13: =_xlfn.XLOOKUP( C13 & "|" & D13 & "|" & E13,#REF!,#REF!, 0 ) -> #REF! | U13: =V13+R13+N13 -> #REF! | V13: =_xlfn.XLOOKUP( C13 & "|" & D13 & "|" & E13,#REF!,#REF!, 0 ) -> #REF! | W13: =T13*I13 -> #REF! | X13: =(V13+N13+R13)*I13 -> #REF! | Y13: =V13*I13 -> #REF!
B14: =B13+1 -> 2 | K14: =IF(V14=0, "판매가 없음", _xlfn.XLOOKUP( C14 & "|" & D14 & "|" & E14,#REF!,#REF!, "0" ) ) -> #REF! | L14: =_xlfn.XLOOKUP( C14 & "|" & D14 & "|" & E14,#REF!,#REF!, 0 ) -> #REF! | M14: =_xlfn.XLOOKUP( C14 & "|" & D14 & "|" & E14,#REF!,#REF!, 0 ) -> #REF! | N14: =_xlfn.XLOOKUP( C14 & "|" & D14 & "|" & E14,#REF!,#REF!, 0 ) -> #REF! | O14: =L14*I14 -> #REF! | P14: =_xlfn.XLOOKUP( C14 & "|" & D14 & "|" & E14,#REF!,#REF!, "차열재 없음" ) -> #REF! | Q14: =_xlfn.XLOOKUP( C14 & "|" & D14 & "|" & E14,#REF!,#REF!, "0" ) -> #REF! | R14: =_xlfn.XLOOKUP( C14 & "|" & D14 & "|" & E14,#REF!,#REF!, "0" ) -> #REF! | S14: =Q14*I14 -> #REF! | T14: =_xlfn.XLOOKUP( C14 & "|" & D14 & "|" & E14,#REF!,#REF!, 0 ) -> #REF! | U14: =V14+R14+N14 -> #REF! | V14: =_xlfn.XLOOKUP( C14 & "|" & D14 & "|" & E14,#REF!,#REF!, 0 ) -> #REF! | W14: =T14*I14 -> #REF! | X14: =(V14+N14+R14)*I14 -> #REF! | Y14: =V14*I14 -> #REF!
B15: =B14+1 -> 3 | K15: =IF(V15=0, "판매가 없음", _xlfn.XLOOKUP( C15 & "|" & D15 & "|" & E15,#REF!,#REF!, "0" ) ) -> #REF! | L15: =_xlfn.XLOOKUP( C15 & "|" & D15 & "|" & E15,#REF!,#REF!, 0 ) -> #REF! | M15: =_xlfn.XLOOKUP( C15 & "|" & D15 & "|" & E15,#REF!,#REF!, 0 ) -> #REF! | N15: =_xlfn.XLOOKUP( C15 & "|" & D15 & "|" & E15,#REF!,#REF!, 0 ) -> #REF! | O15: =L15*I15 -> #REF! | P15: =_xlfn.XLOOKUP( C15 & "|" & D15 & "|" & E15,#REF!,#REF!, "차열재 없음" ) -> #REF! | Q15: =_xlfn.XLOOKUP( C15 & "|" & D15 & "|" & E15,#REF!,#REF!, "0" ) -> #REF! | R15: =_xlfn.XLOOKUP( C15 & "|" & D15 & "|" & E15,#REF!,#REF!, "0" ) -> #REF! | S15: =Q15*I15 -> #REF! | T15: =_xlfn.XLOOKUP( C15 & "|" & D15 & "|" & E15,#REF!,#REF!, 0 ) -> #REF! | U15: =V15+R15+N15 -> #REF! | V15: =_xlfn.XLOOKUP( C15 & "|" & D15 & "|" & E15,#REF!,#REF!, 0 ) -> #REF! | W15: =T15*I15 -> #REF! | X15: =(V15+N15+R15)*I15 -> #REF! | Y15: =V15*I15 -> #REF!
B16: =B15+1 -> 4 | K16: =IF(V16=0, "판매가 없음", _xlfn.XLOOKUP( C16 & "|" & D16 & "|" & E16,#REF!,#REF!, "0" ) ) -> #REF! | L16: =_xlfn.XLOOKUP( C16 & "|" & D16 & "|" & E16,#REF!,#REF!, 0 ) -> #REF! | M16: =_xlfn.XLOOKUP( C16 & "|" & D16 & "|" & E16,#REF!,#REF!, 0 ) -> #REF! | N16: =_xlfn.XLOOKUP( C16 & "|" & D16 & "|" & E16,#REF!,#REF!, 0 ) -> #REF! | O16: =L16*I16 -> #REF! | P16: =_xlfn.XLOOKUP( C16 & "|" & D16 & "|" & E16,#REF!,#REF!, "차열재 없음" ) -> #REF! | Q16: =_xlfn.XLOOKUP( C16 & "|" & D16 & "|" & E16,#REF!,#REF!, "0" ) -> #REF! | R16: =_xlfn.XLOOKUP( C16 & "|" & D16 & "|" & E16,#REF!,#REF!, "0" ) -> #REF! | S16: =Q16*I16 -> #REF! | T16: =_xlfn.XLOOKUP( C16 & "|" & D16 & "|" & E16,#REF!,#REF!, 0 ) -> #REF! | U16: =V16+R16+N16 -> #REF! | V16: =_xlfn.XLOOKUP( C16 & "|" & D16 & "|" & E16,#REF!,#REF!, 0 ) -> #REF! | W16: =T16*I16 -> #REF! | X16: =(V16+N16+R16)*I16 -> #REF! | Y16: =V16*I16 -> #REF!
B17: =B16+1 -> 5 | K17: =IF(V17=0, "판매가 없음", _xlfn.XLOOKUP( C17 & "|" & D17 & "|" & E17,#REF!,#REF!, "0" ) ) -> #REF! | L17: =_xlfn.XLOOKUP( C17 & "|" & D17 & "|" & E17,#REF!,#REF!, 0 ) -> #REF! | M17: =_xlfn.XLOOKUP( C17 & "|" & D17 & "|" & E17,#REF!,#REF!, 0 ) -> #REF! | N17: =_xlfn.XLOOKUP( C17 & "|" & D17 & "|" & E17,#REF!,#REF!, 0 ) -> #REF! | O17: =L17*I17 -> #REF! | P17: =_xlfn.XLOOKUP( C17 & "|" & D17 & "|" & E17,#REF!,#REF!, "차열재 없음" ) -> #REF! | Q17: =_xlfn.XLOOKUP( C17 & "|" & D17 & "|" & E17,#REF!,#REF!, "0" ) -> #REF! | R17: =_xlfn.XLOOKUP( C17 & "|" & D17 & "|" & E17,#REF!,#REF!, "0" ) -> #REF! | S17: =Q17*I17 -> #REF! | T17: =_xlfn.XLOOKUP( C17 & "|" & D17 & "|" & E17,#REF!,#REF!, 0 ) -> #REF! | U17: =V17+R17+N17 -> #REF! | V17: =_xlfn.XLOOKUP( C17 & "|" & D17 & "|" & E17,#REF!,#REF!, 0 ) -> #REF! | W17: =T17*I17 -> #REF! | X17: =(V17+N17+R17)*I17 -> #REF! | Y17: =V17*I17 -> #REF!
B18: =B17+1 -> 6 | K18: =IF(V18=0, "판매가 없음", _xlfn.XLOOKUP( C18 & "|" & D18 & "|" & E18,#REF!,#REF!, "0" ) ) -> #REF! | L18: =_xlfn.XLOOKUP( C18 & "|" & D18 & "|" & E18,#REF!,#REF!, 0 ) -> #REF! | M18: =_xlfn.XLOOKUP( C18 & "|" & D18 & "|" & E18,#REF!,#REF!, 0 ) -> #REF! | N18: =_xlfn.XLOOKUP( C18 & "|" & D18 & "|" & E18,#REF!,#REF!, 0 ) -> #REF! | O18: =L18*I18 -> #REF! | P18: =_xlfn.XLOOKUP( C18 & "|" & D18 & "|" & E18,#REF!,#REF!, "차열재 없음" ) -> #REF! | Q18: =_xlfn.XLOOKUP( C18 & "|" & D18 & "|" & E18,#REF!,#REF!, "0" ) -> #REF! | R18: =_xlfn.XLOOKUP( C18 & "|" & D18 & "|" & E18,#REF!,#REF!, "0" ) -> #REF! | S18: =Q18*I18 -> #REF! | T18: =_xlfn.XLOOKUP( C18 & "|" & D18 & "|" & E18,#REF!,#REF!, 0 ) -> #REF! | U18: =V18+R18+N18 -> #REF! | V18: =_xlfn.XLOOKUP( C18 & "|" & D18 & "|" & E18,#REF!,#REF!, 0 ) -> #REF! | W18: =T18*I18 -> #REF! | X18: =(V18+N18+R18)*I18 -> #REF! | Y18: =V18*I18 -> #REF!
B19: =B18+1 -> 7 | K19: =IF(V19=0, "판매가 없음", _xlfn.XLOOKUP( C19 & "|" & D19 & "|" & E19,#REF!,#REF!, "0" ) ) -> #REF! | L19: =_xlfn.XLOOKUP( C19 & "|" & D19 & "|" & E19,#REF!,#REF!, 0 ) -> #REF! | M19: =_xlfn.XLOOKUP( C19 & "|" & D19 & "|" & E19,#REF!,#REF!, 0 ) -> #REF! | N19: =_xlfn.XLOOKUP( C19 & "|" & D19 & "|" & E19,#REF!,#REF!, 0 ) -> #REF! | O19: =L19*I19 -> #REF! | P19: =_xlfn.XLOOKUP( C19 & "|" & D19 & "|" & E19,#REF!,#REF!, "차열재 없음" ) -> #REF! | Q19: =_xlfn.XLOOKUP( C19 & "|" & D19 & "|" & E19,#REF!,#REF!, "0" ) -> #REF! | R19: =_xlfn.XLOOKUP( C19 & "|" & D19 & "|" & E19,#REF!,#REF!, "0" ) -> #REF! | S19: =Q19*I19 -> #REF! | T19: =_xlfn.XLOOKUP( C19 & "|" & D19 & "|" & E19,#REF!,#REF!, 0 ) -> #REF! | U19: =V19+R19+N19 -> #REF! | V19: =_xlfn.XLOOKUP( C19 & "|" & D19 & "|" & E19,#REF!,#REF!, 0 ) -> #REF! | W19: =T19*I19 -> #REF! | X19: =(V19+N19+R19)*I19 -> #REF! | Y19: =V19*I19 -> #REF!
B20: =B19+1 -> 8 | K20: =IF(V20=0, "판매가 없음", _xlfn.XLOOKUP( C20 & "|" & D20 & "|" & E20,#REF!,#REF!, "0" ) ) -> #REF! | L20: =_xlfn.XLOOKUP( C20 & "|" & D20 & "|" & E20,#REF!,#REF!, 0 ) -> #REF! | M20: =_xlfn.XLOOKUP( C20 & "|" & D20 & "|" & E20,#REF!,#REF!, 0 ) -> #REF! | N20: =_xlfn.XLOOKUP( C20 & "|" & D20 & "|" & E20,#REF!,#REF!, 0 ) -> #REF! | O20: =L20*I20 -> #REF! | P20: =_xlfn.XLOOKUP( C20 & "|" & D20 & "|" & E20,#REF!,#REF!, "차열재 없음" ) -> #REF! | Q20: =_xlfn.XLOOKUP( C20 & "|" & D20 & "|" & E20,#REF!,#REF!, "0" ) -> #REF! | R20: =_xlfn.XLOOKUP( C20 & "|" & D20 & "|" & E20,#REF!,#REF!, "0" ) -> #REF! | S20: =Q20*I20 -> #REF! | T20: =_xlfn.XLOOKUP( C20 & "|" & D20 & "|" & E20,#REF!,#REF!, 0 ) -> #REF! | U20: =V20+R20+N20 -> #REF! | V20: =_xlfn.XLOOKUP( C20 & "|" & D20 & "|" & E20,#REF!,#REF!, 0 ) -> #REF! | W20: =T20*I20 -> #REF! | X20: =(V20+N20+R20)*I20 -> #REF! | Y20: =V20*I20 -> #REF!
B21: =B20+1 -> 9 | K21: =IF(V21=0, "판매가 없음", _xlfn.XLOOKUP( C21 & "|" & D21 & "|" & E21,#REF!,#REF!, "0" ) ) -> #REF! | L21: =_xlfn.XLOOKUP( C21 & "|" & D21 & "|" & E21,#REF!,#REF!, 0 ) -> #REF! | M21: =_xlfn.XLOOKUP( C21 & "|" & D21 & "|" & E21,#REF!,#REF!, 0 ) -> #REF! | N21: =_xlfn.XLOOKUP( C21 & "|" & D21 & "|" & E21,#REF!,#REF!, 0 ) -> #REF! | O21: =L21*I21 -> #REF! | P21: =_xlfn.XLOOKUP( C21 & "|" & D21 & "|" & E21,#REF!,#REF!, "차열재 없음" ) -> #REF! | Q21: =_xlfn.XLOOKUP( C21 & "|" & D21 & "|" & E21,#REF!,#REF!, "0" ) -> #REF! | R21: =_xlfn.XLOOKUP( C21 & "|" & D21 & "|" & E21,#REF!,#REF!, "0" ) -> #REF! | S21: =Q21*I21 -> #REF! | T21: =_xlfn.XLOOKUP( C21 & "|" & D21 & "|" & E21,#REF!,#REF!, 0 ) -> #REF! | U21: =V21+R21+N21 -> #REF! | V21: =_xlfn.XLOOKUP( C21 & "|" & D21 & "|" & E21,#REF!,#REF!, 0 ) -> #REF! | W21: =T21*I21 -> #REF! | X21: =(V21+N21+R21)*I21 -> #REF! | Y21: =V21*I21 -> #REF!
B22: =B21+1 -> 10 | K22: =IF(V22=0, "판매가 없음", _xlfn.XLOOKUP( C22 & "|" & D22 & "|" & E22,#REF!,#REF!, "0" ) ) -> #REF! | L22: =_xlfn.XLOOKUP( C22 & "|" & D22 & "|" & E22,#REF!,#REF!, 0 ) -> #REF! | M22: =_xlfn.XLOOKUP( C22 & "|" & D22 & "|" & E22,#REF!,#REF!, 0 ) -> #REF! | N22: =_xlfn.XLOOKUP( C22 & "|" & D22 & "|" & E22,#REF!,#REF!, 0 ) -> #REF! | O22: =L22*I22 -> #REF! | P22: =_xlfn.XLOOKUP( C22 & "|" & D22 & "|" & E22,#REF!,#REF!, "차열재 없음" ) -> #REF! | Q22: =_xlfn.XLOOKUP( C22 & "|" & D22 & "|" & E22,#REF!,#REF!, "0" ) -> #REF! | R22: =_xlfn.XLOOKUP( C22 & "|" & D22 & "|" & E22,#REF!,#REF!, "0" ) -> #REF! | S22: =Q22*I22 -> #REF! | T22: =_xlfn.XLOOKUP( C22 & "|" & D22 & "|" & E22,#REF!,#REF!, 0 ) -> #REF! | U22: =V22+R22+N22 -> #REF! | V22: =_xlfn.XLOOKUP( C22 & "|" & D22 & "|" & E22,#REF!,#REF!, 0 ) -> #REF! | W22: =T22*I22 -> #REF! | X22: =(V22+N22+R22)*I22 -> #REF! | Y22: =V22*I22 -> #REF!
B23: =B22+1 -> 11 | K23: =IF(V23=0, "판매가 없음", _xlfn.XLOOKUP( C23 & "|" & D23 & "|" & E23,#REF!,#REF!, "0" ) ) -> #REF! | L23: =_xlfn.XLOOKUP( C23 & "|" & D23 & "|" & E23,#REF!,#REF!, 0 ) -> #REF! | M23: =_xlfn.XLOOKUP( C23 & "|" & D23 & "|" & E23,#REF!,#REF!, 0 ) -> #REF! | N23: =_xlfn.XLOOKUP( C23 & "|" & D23 & "|" & E23,#REF!,#REF!, 0 ) -> #REF! | O23: =L23*I23 -> #REF! | P23: =_xlfn.XLOOKUP( C23 & "|" & D23 & "|" & E23,#REF!,#REF!, "차열재 없음" ) -> #REF! | Q23: =_xlfn.XLOOKUP( C23 & "|" & D23 & "|" & E23,#REF!,#REF!, "0" ) -> #REF! | R23: =_xlfn.XLOOKUP( C23 & "|" & D23 & "|" & E23,#REF!,#REF!, "0" ) -> #REF! | S23: =Q23*I23 -> #REF! | T23: =_xlfn.XLOOKUP( C23 & "|" & D23 & "|" & E23,#REF!,#REF!, 0 ) -> #REF! | U23: =V23+R23+N23 -> #REF! | V23: =_xlfn.XLOOKUP( C23 & "|" & D23 & "|" & E23,#REF!,#REF!, 0 ) -> #REF! | W23: =T23*I23 -> #REF! | X23: =(V23+N23+R23)*I23 -> #REF! | Y23: =V23*I23 -> #REF!
B24: =B23+1 -> 12 | K24: =IF(V24=0, "판매가 없음", _xlfn.XLOOKUP( C24 & "|" & D24 & "|" & E24,#REF!,#REF!, "0" ) ) -> #REF! | L24: =_xlfn.XLOOKUP( C24 & "|" & D24 & "|" & E24,#REF!,#REF!, 0 ) -> #REF! | M24: =_xlfn.XLOOKUP( C24 & "|" & D24 & "|" & E24,#REF!,#REF!, 0 ) -> #REF! | N24: =_xlfn.XLOOKUP( C24 & "|" & D24 & "|" & E24,#REF!,#REF!, 0 ) -> #REF! | O24: =L24*I24 -> #REF! | P24: =_xlfn.XLOOKUP( C24 & "|" & D24 & "|" & E24,#REF!,#REF!, "차열재 없음" ) -> #REF! | Q24: =_xlfn.XLOOKUP( C24 & "|" & D24 & "|" & E24,#REF!,#REF!, "0" ) -> #REF! | R24: =_xlfn.XLOOKUP( C24 & "|" & D24 & "|" & E24,#REF!,#REF!, "0" ) -> #REF! | S24: =Q24*I24 -> #REF! | T24: =_xlfn.XLOOKUP( C24 & "|" & D24 & "|" & E24,#REF!,#REF!, 0 ) -> #REF! | U24: =V24+R24+N24 -> #REF! | V24: =_xlfn.XLOOKUP( C24 & "|" & D24 & "|" & E24,#REF!,#REF!, 0 ) -> #REF! | W24: =T24*I24 -> #REF! | X24: =(V24+N24+R24)*I24 -> #REF! | Y24: =V24*I24 -> #REF!
B25: =B24+1 -> 13 | K25: =IF(V25=0, "판매가 없음", _xlfn.XLOOKUP( C25 & "|" & D25 & "|" & E25,#REF!,#REF!, "0" ) ) -> #REF! | L25: =_xlfn.XLOOKUP( C25 & "|" & D25 & "|" & E25,#REF!,#REF!, 0 ) -> #REF! | M25: =_xlfn.XLOOKUP( C25 & "|" & D25 & "|" & E25,#REF!,#REF!, 0 ) -> #REF! | N25: =_xlfn.XLOOKUP( C25 & "|" & D25 & "|" & E25,#REF!,#REF!, 0 ) -> #REF! | O25: =L25*I25 -> #REF! | P25: =_xlfn.XLOOKUP( C25 & "|" & D25 & "|" & E25,#REF!,#REF!, "차열재 없음" ) -> #REF! | Q25: =_xlfn.XLOOKUP( C25 & "|" & D25 & "|" & E25,#REF!,#REF!, "0" ) -> #REF! | R25: =_xlfn.XLOOKUP( C25 & "|" & D25 & "|" & E25,#REF!,#REF!, "0" ) -> #REF! | S25: =Q25*I25 -> #REF! | T25: =_xlfn.XLOOKUP( C25 & "|" & D25 & "|" & E25,#REF!,#REF!, 0 ) -> #REF! | U25: =V25+R25+N25 -> #REF! | V25: =_xlfn.XLOOKUP( C25 & "|" & D25 & "|" & E25,#REF!,#REF!, 0 ) -> #REF! | W25: =T25*I25 -> #REF! | X25: =(V25+N25+R25)*I25 -> #REF! | Y25: =V25*I25 -> #REF!
... B81: =B80+1 -> 69 | K81: =IF(V81=0, "판매가 없음", _xlfn.XLOOKUP( C81 & "|" & D81 & "|" & E81,#REF!,#REF!, "0" ) ) -> #REF! | L81: =_xlfn.XLOOKUP( C81 & "|" & D81 & "|" & E81,#REF!,#REF!, 0 ) -> #REF! | M81: =_xlfn.XLOOKUP( C81 & "|" & D81 & "|" & E81,#REF!,#REF!, 0 ) -> #REF! | N81: =_xlfn.XLOOKUP( C81 & "|" & D81 & "|" & E81,#REF!,#REF!, 0 ) -> #REF! | O81: =L81*I81 -> #REF! | P81: =_xlfn.XLOOKUP( C81 & "|" & D81 & "|" & E81,#REF!,#REF!, "차열재 없음" ) -> #REF! | Q81: =_xlfn.XLOOKUP( C81 & "|" & D81 & "|" & E81,#REF!,#REF!, "0" ) -> #REF! | R81: =_xlfn.XLOOKUP( C81 & "|" & D81 & "|" & E81,#REF!,#REF!, "0" ) -> #REF! | S81: =Q81*I81 -> #REF! | T81: =_xlfn.XLOOKUP( C81 & "|" & D81 & "|" & E81,#REF!,#REF!, 0 ) -> #REF! | U81: =V81+R81+N81 -> #REF! | V81: =_xlfn.XLOOKUP( C81 & "|" & D81 & "|" & E81,#REF!,#REF!, 0 ) -> #REF! | W81: =T81*I81 -> #REF! | X81: =(V81+N81+R81)*I81 -> #REF! | Y81: =V81*I81 -> #REF!
B82: =B81+1 -> 70
B83: =B82+1 -> 71
B84: =B83+1 -> 72
B85: =B84+1 -> 73
B86: =B85+1 -> 74
B87: =B86+1 -> 75
B88: =B87+1 -> 76
B89: =B88+1 -> 77
B90: =B89+1 -> 78
B91: =B90+1 -> 79
B92: =B91+1 -> 80
B93: =B92+1 -> 81
... B100: =B99+1 -> 88
B101: =B100+1 -> 89 | C101: 차열재 및 실란트 산출
B102: =B101+1 -> 90 | C102: 차열재 25T*200*7200 | H102: 롤 | I102: =_xlfn.XLOOKUP(C102, $B$120:$B$127, $E$120:$E$127, "") -> 0 | T102: =#REF! -> #REF! | V102: =#REF! -> #REF! | W102: =T102*I102 -> #REF! | Y102: =V102*I102 -> #REF!
B103: =B102+1 -> 91 | C103: 차열재 25T*400*7200 | H103: 롤 | I103: =_xlfn.XLOOKUP(C103, $B$120:$B$127, $E$120:$E$127, "") -> 0 | T103: =#REF! -> #REF! | V103: =#REF! -> #REF! | W103: =T103*I103 -> #REF! | Y103: =V103*I103 -> #REF!
B104: =B103+1 -> 92 | C104: 차열재 38T*200*4800 | H104: 롤 | I104: =_xlfn.XLOOKUP(C104, $B$120:$B$127, $E$120:$E$127, "") -> 0 | T104: =#REF! -> #REF! | V104: =#REF! -> #REF! | W104: =T104*I104 -> #REF! | Y104: =V104*I104 -> #REF!
B105: =B104+1 -> 93 | C105: 차열재 38T*400*4800 | H105: 롤 | I105: =_xlfn.XLOOKUP(C105, $B$120:$B$127, $E$120:$E$127, "") -> 0 | T105: =#REF! -> #REF! | V105: =#REF! -> #REF!
B106: =B105+1 -> 94 | C106: 차열재 38T*600*4800 | H106: 롤 | I106: =_xlfn.XLOOKUP(C106, $B$120:$B$127, $E$120:$E$127, "") -> 0 | T106: =#REF! -> #REF! | V106: =#REF! -> #REF!
B107: =B106+1 -> 95 | C107: 차열재 50T*200*3600 | H107: 롤 | I107: =_xlfn.XLOOKUP(C107, $B$120:$B$127, $E$120:$E$127, "") -> 0
B108: =B107+1 -> 96 | C108: 차열재 50T*400*3600 | H108: 롤 | I108: =_xlfn.XLOOKUP(C108, $B$120:$B$127, $E$120:$E$127, "") -> 0
...

Sheet 2-1.고정구단가산출<출력용>
B2: 발주의뢰처 | C2: ='1.발주접수'!C5 -> 예시용 | E2: 현장명 | F2: ='1.발주접수'!C8 -> 현장명 예시
B5: 고정구 견적서 단가 산출
C6: 검색 품명 | D6: 배관 | E6: 슬리브 | F6: 격적서 품명 | G6: 규격 | H6: 단위 | I6: 수량 | J6: 적요 | K6: 단가 | L6: 판매가 | M6: 단가 기준 금액 | N6: 금액
B7: 1 | C7: ='2.고정구단가산출'!C13 -> 벽체_강관 | D7: ='2.고정구단가산출'!D13 -> 벽체_강관_15A | E7: ='2.고정구단가산출'!E13 -> 50A | F7: ='2.고정구단가산출'!F13 -> 내화채움구조(벽체,강관용) | G7: ='2.고정구단가산출'!G13 -> 15*25 | H7: ='2.고정구단가산출'!H13 -> 개소 | I7: ='2.고정구단가산출'!I13 -> 3 | K7: ='2.고정구단가산출'!T13 -> #REF! | L7: ='2.고정구단가산출'!V13 -> #REF! | M7: ='2.고정구단가산출'!W13 -> #REF! | N7: ='2.고정구단가산출'!Y13 -> #REF!
B8: =B7+1 -> 2 | C8: ='2.고정구단가산출'!C14 -> 0 | D8: ='2.고정구단가산출'!D14 -> 0 | E8: ='2.고정구단가산출'!E14 -> 0 | F8: ='2.고정구단가산출'!F14 -> 0 | G8: ='2.고정구단가산출'!G14 -> 0 | H8: ='2.고정구단가산출'!H14 -> 0 | I8: ='2.고정구단가산출'!I14 -> 0 | K8: ='2.고정구단가산출'!T14 -> #REF! | L8: ='2.고정구단가산출'!V14 -> #REF! | M8: ='2.고정구단가산출'!W14 -> #REF! | N8: ='2.고정구단가산출'!Y14 -> #REF!
B9: =B8+1 -> 3 | C9: ='2.고정구단가산출'!C15 -> 0 | D9: ='2.고정구단가산출'!D15 -> 0 | E9: ='2.고정구단가산출'!E15 -> 0 | F9: ='2.고정구단가산출'!F15 -> 0 | G9: ='2.고정구단가산출'!G15 -> 0 | H9: ='2.고정구단가산출'!H15 -> 0 | I9: ='2.고정구단가산출'!I15 -> 0 | K9: ='2.고정구단가산출'!T15 -> #REF! | L9: ='2.고정구단가산출'!V15 -> #REF! | M9: ='2.고정구단가산출'!W15 -> #REF! | N9: ='2.고정구단가산출'!Y15 -> #REF!
B10: =B9+1 -> 4 | C10: ='2.고정구단가산출'!C16 -> 0 | D10: ='2.고정구단가산출'!D16 -> 0 | E10: ='2.고정구단가산출'!E16 -> 0 | F10: ='2.고정구단가산출'!F16 -> 0 | G10: ='2.고정구단가산출'!G16 -> 0 | H10: ='2.고정구단가산출'!H16 -> 0 | I10: ='2.고정구단가산출'!I16 -> 0 | K10: ='2.고정구단가산출'!T16 -> #REF! | L10: ='2.고정구단가산출'!V16 -> #REF! | M10: ='2.고정구단가산출'!W16 -> #REF! | N10: ='2.고정구단가산출'!Y16 -> #REF!
B11: =B10+1 -> 5 | C11: ='2.고정구단가산출'!C17 -> 0 | D11: ='2.고정구단가산출'!D17 -> 0 | E11: ='2.고정구단가산출'!E17 -> 0 | F11: ='2.고정구단가산출'!F17 -> 0 | G11: ='2.고정구단가산출'!G17 -> 0 | H11: ='2.고정구단가산출'!H17 -> 0 | I11: ='2.고정구단가산출'!I17 -> 0 | K11: ='2.고정구단가산출'!T17 -> #REF! | L11: ='2.고정구단가산출'!V17 -> #REF! | M11: ='2.고정구단가산출'!W17 -> #REF! | N11: ='2.고정구단가산출'!Y17 -> #REF!
B12: =B11+1 -> 6 | C12: ='2.고정구단가산출'!C18 -> 0 | D12: ='2.고정구단가산출'!D18 -> 0 | E12: ='2.고정구단가산출'!E18 -> 0 | F12: ='2.고정구단가산출'!F18 -> 0 | G12: ='2.고정구단가산출'!G18 -> 0 | H12: ='2.고정구단가산출'!H18 -> 0 | I12: ='2.고정구단가산출'!I18 -> 0 | K12: ='2.고정구단가산출'!T18 -> #REF! | L12: ='2.고정구단가산출'!V18 -> #REF! | M12: ='2.고정구단가산출'!W18 -> #REF! | N12: ='2.고정구단가산출'!Y18 -> #REF!
B13: =B12+1 -> 7 | C13: ='2.고정구단가산출'!C110 -> 0 | D13: ='2.고정구단가산출'!D110 -> 0 | E13: ='2.고정구단가산출'!E110 -> 0 | F13: ='2.고정구단가산출'!F110 -> 0 | G13: ='2.고정구단가산출'!G110 -> 0 | H13: ='2.고정구단가산출'!H110 -> 0 | I13: ='2.고정구단가산출'!I110 -> 0 | K13: ='2.고정구단가산출'!T110 -> 0 | L13: ='2.고정구단가산출'!V110 -> 0 | M13: ='2.고정구단가산출'!W110 -> 0 | N13: ='2.고정구단가산출'!Y110 -> 0
B14: =B13+1 -> 8 | C14: ='2.고정구단가산출'!C111 -> 0 | D14: ='2.고정구단가산출'!D111 -> 0 | E14: ='2.고정구단가산출'!E111 -> 0 | F14: ='2.고정구단가산출'!F111 -> 0 | G14: ='2.고정구단가산출'!G111 -> 0 | H14: ='2.고정구단가산출'!H111 -> 0 | I14: ='2.고정구단가산출'!I111 -> 0 | K14: ='2.고정구단가산출'!T111 -> 0 | L14: ='2.고정구단가산출'!V111 -> 0 | M14: ='2.고정구단가산출'!W111 -> #REF! | N14: ='2.고정구단가산출'!Y111 -> #REF!
K15: 견적서 금액 합계
K17: ='2.고정구단가산출'!T114 -> #REF!
K20: 매출 | N20: ='2.고정구단가산출'!Y117 -> #REF!
K22: 매입 | N22: ='2.고정구단가산출'!Y119 -> #REF!
K24: 순이익 | N24: ='2.고정구단가산출'!Y121 -> #REF!
K26: 이익률 | N26: ='2.고정구단가산출'!Y123 -> #REF!

Sheet 3.견적서
A2: 탑 디뉴스 ( Total Of fireProof Material )
A4: 견 적 서
L9: ='1.발주접수'!$C$5 -> 예시용 | M9: 귀중 | P9: 주식회사 탑디뉴스 대표 이민수
L11: 견 적 번 호 | M11: =TEXT(M12,"yyyy-mm-dd") -> 2026-02-05 | P11: 경기도 화성시 동탄대로 636-3, C동 1206호
L12: 견 적 일 자 | M12: ='1.발주접수'!$C$6 -> 46058 | P12: t) 010-8884-4742 f) 031-8056-9544
L13: 현 장 명 | M13: ='1.발주접수'!$C$8 -> 현장명 예시 | P13: e-mail) topdi@topdignus.co.kr
B16: 하기와 같이 필립산업 배관을 견적합니다.
B18: ="[납품금액]"&"一金"&NUMBERSTRING(G53,1)&"원정" -> #REF! | I18: 부가세 별도
A20: 번호 | B20: 품 목 | C20: 규격 (배관 * 슬리브) | D20: 단위 | E20: 수량 | F20: 단가 | G20: 금액 | H20: 비고 | I20: 차열재
A21: 1 | B21: ='2.고정구단가산출'!F13 -> 내화채움구조(벽체,강관용) | C21: ='2.고정구단가산출'!G13 -> 15*25 | D21: ='2.고정구단가산출'!H13 -> 개소 | E21: ='2.고정구단가산출'!I13 -> 3 | F21: ='2.고정구단가산출'!V13 -> #REF! | G21: =F21*E21 -> #REF! | H21: ='2.고정구단가산출'!K13 -> #REF! | I21: ='2.고정구단가산출'!P13 -> #REF!
A22: =A21+1 -> 2 | B22: ='2.고정구단가산출'!F14 -> 0 | C22: ='2.고정구단가산출'!G14 -> 0 | D22: ='2.고정구단가산출'!H14 -> 0 | E22: ='2.고정구단가산출'!I14 -> 0 | F22: ='2.고정구단가산출'!V14 -> #REF! | G22: =F22*E22 -> #REF! | H22: ='2.고정구단가산출'!K14 -> #REF! | I22: ='2.고정구단가산출'!P14 -> #REF!
A23: =A22+1 -> 3 | B23: ='2.고정구단가산출'!F15 -> 0 | C23: ='2.고정구단가산출'!G15 -> 0 | D23: ='2.고정구단가산출'!H15 -> 0 | E23: ='2.고정구단가산출'!I15 -> 0 | F23: ='2.고정구단가산출'!V15 -> #REF! | G23: =F23*E23 -> #REF! | H23: ='2.고정구단가산출'!K15 -> #REF! | I23: ='2.고정구단가산출'!P15 -> #REF!
A24: =A23+1 -> 4 | B24: ='2.고정구단가산출'!F16 -> 0 | C24: ='2.고정구단가산출'!G16 -> 0 | D24: ='2.고정구단가산출'!H16 -> 0 | E24: ='2.고정구단가산출'!I16 -> 0 | F24: ='2.고정구단가산출'!V16 -> #REF! | G24: =F24*E24 -> #REF! | H24: ='2.고정구단가산출'!K16 -> #REF! | I24: ='2.고정구단가산출'!P16 -> #REF!
A25: =A24+1 -> 5 | B25: ='2.고정구단가산출'!F17 -> 0 | C25: ='2.고정구단가산출'!G17 -> 0 | D25: ='2.고정구단가산출'!H17 -> 0 | E25: ='2.고정구단가산출'!I17 -> 0 | F25: ='2.고정구단가산출'!V17 -> #REF! | G25: =F25*E25 -> #REF! | H25: ='2.고정구단가산출'!K17 -> #REF! | I25: ='2.고정구단가산출'!P17 -> #REF!
A26: =A25+1 -> 6 | B26: ='2.고정구단가산출'!F18 -> 0 | C26: ='2.고정구단가산출'!G18 -> 0 | D26: ='2.고정구단가산출'!H18 -> 0 | E26: ='2.고정구단가산출'!I18 -> 0 | F26: ='2.고정구단가산출'!V18 -> #REF! | G26: =F26*E26 -> #REF! | H26: ='2.고정구단가산출'!K18 -> #REF! | I26: ='2.고정구단가산출'!P18 -> #REF!
A27: =A26+1 -> 7 | B27: ='2.고정구단가산출'!F19 -> 0 | C27: ='2.고정구단가산출'!G19 -> 0 | D27: ='2.고정구단가산출'!H19 -> 0 | E27: ='2.고정구단가산출'!I19 -> 0 | F27: ='2.고정구단가산출'!V19 -> #REF! | G27: =F27*E27 -> #REF! | H27: ='2.고정구단가산출'!K19 -> #REF! | I27: ='2.고정구단가산출'!P19 -> #REF!
A28: =A27+1 -> 8 | B28: ='2.고정구단가산출'!F20 -> 0 | C28: ='2.고정구단가산출'!G20 -> 0 | D28: ='2.고정구단가산출'!H20 -> 0 | E28: ='2.고정구단가산출'!I20 -> 0 | F28: ='2.고정구단가산출'!V20 -> #REF! | G28: =F28*E28 -> #REF! | H28: ='2.고정구단가산출'!K20 -> #REF! | I28: ='2.고정구단가산출'!P20 -> #REF!
A29: =A28+1 -> 9 | B29: ='2.고정구단가산출'!F21 -> 0 | C29: ='2.고정구단가산출'!G21 -> 0 | D29: ='2.고정구단가산출'!H21 -> 0 | E29: ='2.고정구단가산출'!I21 -> 0 | F29: ='2.고정구단가산출'!V21 -> #REF! | G29: =F29*E29 -> #REF! | I29: ='2.고정구단가산출'!P21 -> #REF!
A30: =A29+1 -> 10 | B30: ='2.고정구단가산출'!F22 -> 0 | C30: ='2.고정구단가산출'!G22 -> 0 | D30: ='2.고정구단가산출'!H22 -> 0 | E30: ='2.고정구단가산출'!I22 -> 0 | F30: ='2.고정구단가산출'!V22 -> #REF! | G30: =F30*E30 -> #REF! | I30: ='2.고정구단가산출'!P22 -> #REF!
A31: =A30+1 -> 11 | B31: ='2.고정구단가산출'!F23 -> 0 | C31: ='2.고정구단가산출'!G23 -> 0 | D31: ='2.고정구단가산출'!H23 -> 0 | E31: ='2.고정구단가산출'!I23 -> 0 | F31: ='2.고정구단가산출'!V23 -> #REF! | G31: =F31*E31 -> #REF! | I31: ='2.고정구단가산출'!P23 -> #REF!
A32: =A31+1 -> 12 | B32: ='2.고정구단가산출'!F24 -> 0 | C32: ='2.고정구단가산출'!G24 -> 0 | D32: ='2.고정구단가산출'!H24 -> 0 | E32: ='2.고정구단가산출'!I24 -> 0 | F32: ='2.고정구단가산출'!V24 -> #REF! | G32: =F32*E32 -> #REF! | I32: ='2.고정구단가산출'!P24 -> #REF!
A33: =A32+1 -> 13 | B33: ='2.고정구단가산출'!F25 -> 0 | C33: ='2.고정구단가산출'!G25 -> 0 | D33: ='2.고정구단가산출'!H25 -> 0 | E33: ='2.고정구단가산출'!I25 -> 0 | F33: ='2.고정구단가산출'!V25 -> #REF! | G33: =F33*E33 -> #REF! | I33: ='2.고정구단가산출'!P25 -> #REF!
A34: =A33+1 -> 14 | B34: ='2.고정구단가산출'!F26 -> 0 | C34: ='2.고정구단가산출'!G26 -> 0 | D34: ='2.고정구단가산출'!H26 -> 0 | E34: ='2.고정구단가산출'!I26 -> 0 | F34: ='2.고정구단가산출'!V26 -> #REF! | G34: =F34*E34 -> #REF! | I34: ='2.고정구단가산출'!P26 -> #REF!
A35: =A34+1 -> 15 | B35: ='2.고정구단가산출'!F27 -> 0 | C35: ='2.고정구단가산출'!G27 -> 0 | D35: ='2.고정구단가산출'!H27 -> 0 | E35: ='2.고정구단가산출'!I27 -> 0 | F35: ='2.고정구단가산출'!V27 -> #REF! | G35: =F35*E35 -> #REF! | H35: ='2.고정구단가산출'!K27 -> #REF! | I35: ='2.고정구단가산출'!P27 -> #REF!
A36: =A35+1 -> 16 | B36: ='2.고정구단가산출'!F28 -> 0 | C36: ='2.고정구단가산출'!G28 -> 0 | D36: ='2.고정구단가산출'!H28 -> 0 | E36: ='2.고정구단가산출'!I28 -> 0 | F36: ='2.고정구단가산출'!V28 -> #REF! | G36: =F36*E36 -> #REF! | H36: ='2.고정구단가산출'!K28 -> #REF! | I36: ='2.고정구단가산출'!P28 -> #REF!
A37: =A36+1 -> 17 | B37: ='2.고정구단가산출'!F29 -> 0 | C37: ='2.고정구단가산출'!G29 -> 0 | D37: ='2.고정구단가산출'!H29 -> 0 | E37: ='2.고정구단가산출'!I29 -> 0 | F37: ='2.고정구단가산출'!V29 -> #REF! | G37: =F37*E37 -> #REF! | H37: ='2.고정구단가산출'!K29 -> #REF! | I37: ='2.고정구단가산출'!P29 -> #REF!
A38: =A37+1 -> 18 | B38: ='2.고정구단가산출'!F30 -> 0 | C38: ='2.고정구단가산출'!G30 -> 0 | D38: ='2.고정구단가산출'!H30 -> 0 | E38: ='2.고정구단가산출'!I30 -> 0 | F38: ='2.고정구단가산출'!V30 -> #REF! | G38: =F38*E38 -> #REF! | H38: ='2.고정구단가산출'!K30 -> #REF! | I38: ='2.고정구단가산출'!P30 -> #REF!
A39: =A38+1 -> 19 | B39: ='2.고정구단가산출'!F31 -> 0 | C39: ='2.고정구단가산출'!G31 -> 0 | D39: ='2.고정구단가산출'!H31 -> 0 | E39: ='2.고정구단가산출'!I31 -> 0 | F39: ='2.고정구단가산출'!V31 -> #REF! | G39: =F39*E39 -> #REF! | H39: ='2.고정구단가산출'!K31 -> #REF! | I39: ='2.고정구단가산출'!P31 -> #REF!
A40: =A39+1 -> 20 | B40: ='2.고정구단가산출'!F32 -> 0 | C40: ='2.고정구단가산출'!G32 -> 0 | D40: ='2.고정구단가산출'!H32 -> 0 | E40: ='2.고정구단가산출'!I32 -> 0 | F40: ='2.고정구단가산출'!V32 -> #REF! | G40: =F40*E40 -> #REF!
A41: =A40+1 -> 21 | B41: ='2.고정구단가산출'!F33 -> 0 | C41: ='2.고정구단가산출'!G33 -> 0 | D41: ='2.고정구단가산출'!H33 -> 0 | E41: ='2.고정구단가산출'!I33 -> 0 | F41: ='2.고정구단가산출'!V33 -> #REF! | G41: =F41*E41 -> #REF!
A42: =A41+1 -> 22 | B42: ='2.고정구단가산출'!F34 -> 0 | C42: ='2.고정구단가산출'!G34 -> 0 | D42: ='2.고정구단가산출'!H34 -> 0 | E42: ='2.고정구단가산출'!I34 -> 0 | F42: ='2.고정구단가산출'!V34 -> #REF! | G42: =F42*E42 -> #REF!
A43: =A42+1 -> 23 | B43: ='2.고정구단가산출'!F35 -> 0 | C43: ='2.고정구단가산출'!G35 -> 0 | D43: ='2.고정구단가산출'!H35 -> 0 | E43: ='2.고정구단가산출'!I35 -> 0 | F43: ='2.고정구단가산출'!V35 -> #REF! | G43: =F43*E43 -> #REF!
A44: =A43+1 -> 24 | B44: ='2.고정구단가산출'!F36 -> 0 | C44: ='2.고정구단가산출'!G36 -> 0 | D44: ='2.고정구단가산출'!H36 -> 0 | E44: ='2.고정구단가산출'!I36 -> 0 | F44: ='2.고정구단가산출'!V36 -> #REF! | G44: =F44*E44 -> #REF!
A45: =A44+1 -> 25 | B45: ='2.고정구단가산출'!F37 -> 0 | C45: ='2.고정구단가산출'!G37 -> 0 | D45: ='2.고정구단가산출'!H37 -> 0 | E45: ='2.고정구단가산출'!I37 -> 0 | F45: ='2.고정구단가산출'!V37 -> #REF! | G45: =F45*E45 -> #REF!
A46: =A45+1 -> 26 | B46: ='2.고정구단가산출'!F38 -> 0 | C46: ='2.고정구단가산출'!G38 -> 0 | D46: ='2.고정구단가산출'!H38 -> 0 | E46: ='2.고정구단가산출'!I38 -> 0 | F46: ='2.고정구단가산출'!V38 -> #REF! | G46: =F46*E46 -> #REF! | H46: ='2.고정구단가산출'!K38 -> #REF!
A47: =A46+1 -> 27 | B47: ='2.고정구단가산출'!F39 -> 0 | C47: ='2.고정구단가산출'!G39 -> 0 | D47: ='2.고정구단가산출'!H39 -> 0 | E47: ='2.고정구단가산출'!I39 -> 0 | F47: ='2.고정구단가산출'!V39 -> #REF! | G47: =F47*E47 -> #REF! | I47: ='2.고정구단가산출'!P39 -> #REF!
A48: =A47+1 -> 28 | B48: ='2.고정구단가산출'!F40 -> 0 | C48: ='2.고정구단가산출'!G40 -> 0 | D48: ='2.고정구단가산출'!H40 -> 0 | E48: ='2.고정구단가산출'!I40 -> 0 | F48: ='2.고정구단가산출'!V40 -> #REF! | G48: =F48*E48 -> #REF! | H48: ='2.고정구단가산출'!K40 -> #REF!
A49: =A48+1 -> 29 | B49: ='2.고정구단가산출'!F41 -> 0 | C49: ='2.고정구단가산출'!G41 -> 0 | D49: ='2.고정구단가산출'!H41 -> 0 | E49: ='2.고정구단가산출'!I41 -> 0 | F49: ='2.고정구단가산출'!V41 -> #REF! | G49: =F49*E49 -> #REF! | H49: ='2.고정구단가산출'!K41 -> #REF!
A50: =#REF!+1 -> #REF!
A51: =A50+1 -> #REF!
...

Sheet 4.거래명세서
A2: 탑 디뉴스 ( Total Of fireProof Material )
A4: 거 래 명 세 서
A5: 배관
K11: ='1.발주접수'!$C$5 -> 예시용 | L11: 귀중 | N11: 주식회사 탑디뉴스 대표 이민수
K13: 납품번호 | L13: =TEXT(L14,"yyyy-mm-dd") -> 2026-02-19 | N13: 경기도 화성시 동탄대로 636-3, C동 1206호
K14: 납품일자 | L14: ='1.발주접수'!$C$7 -> 46072 | N14: t) 010-8884-4742 f) 031-8056-9544
K15: 현 장 명 | L15: ='1.발주접수'!$C$8 -> 현장명 예시 | N15: e-mail) profire7006@hanmail.net
A17: [ 납품금액 ] | C17: ="一金"&NUMBERSTRING('3.견적서'!G53,1)&"원정" -> #REF! | H17: 부가세 별도
A18: ='3.견적서'!A20 -> 번호 | B18: ='3.견적서'!B20 -> 품 목 | C18: ='3.견적서'!C20 -> 규격 (배관 * 슬리브) | D18: ='3.견적서'!D20 -> 단위 | E18: ='3.견적서'!E20 -> 수량 | F18: ='3.견적서'!F20 -> 단가 | G18: ='3.견적서'!G20 -> 금액 | H18: ='3.견적서'!H20 -> 비고
A19: 1 | B19: ='3.견적서'!B21 -> 내화채움구조(벽체,강관용) | C19: ='3.견적서'!C21 -> 15*25 | D19: ='3.견적서'!D21 -> 개소 | E19: ='3.견적서'!E21 -> 3 | F19: ='3.견적서'!F21 -> #REF! | G19: ='3.견적서'!G21 -> #REF!
A20: =A19+1 -> 2 | B20: ='3.견적서'!B22 -> 0 | C20: ='3.견적서'!C22 -> 0 | D20: ='3.견적서'!D22 -> 0 | E20: ='3.견적서'!E22 -> 0 | F20: ='3.견적서'!F22 -> #REF! | G20: ='3.견적서'!G22 -> #REF!
A21: =A20+1 -> 3 | B21: ='3.견적서'!B23 -> 0 | C21: ='3.견적서'!C23 -> 0 | D21: ='3.견적서'!D23 -> 0 | E21: ='3.견적서'!E23 -> 0 | F21: ='3.견적서'!F23 -> #REF! | G21: ='3.견적서'!G23 -> #REF!
A22: =A21+1 -> 4 | B22: ='3.견적서'!B24 -> 0 | C22: ='3.견적서'!C24 -> 0 | D22: ='3.견적서'!D24 -> 0 | E22: ='3.견적서'!E24 -> 0 | F22: ='3.견적서'!F24 -> #REF! | G22: ='3.견적서'!G24 -> #REF!
A23: =A22+1 -> 5 | B23: ='3.견적서'!B25 -> 0 | C23: ='3.견적서'!C25 -> 0 | D23: ='3.견적서'!D25 -> 0 | E23: ='3.견적서'!E25 -> 0 | F23: ='3.견적서'!F25 -> #REF! | G23: ='3.견적서'!G25 -> #REF!
A24: =A23+1 -> 6
A25: =A24+1 -> 7 | B25: ='3.견적서'!B52 -> 운임비 | C25: ='3.견적서'!C52 -> 0 | D25: ='3.견적서'!D52 -> 0 | E25: ='3.견적서'!E52 -> 1 | F25: ='3.견적서'!F52 -> 0 | G25: ='3.견적서'!G52 -> 0
A26: =A25+1 -> 8 | B26: ='3.견적서'!B53 -> 계 | C26: ='3.견적서'!C53 -> 0 | D26: ='3.견적서'!D53 -> 0 | E26: ='3.견적서'!E53 -> 0 | F26: ='3.견적서'!F53 -> 0 | G26: ='3.견적서'!G53 -> #REF!

Sheet 5.발주서 
A1: 자 재 발 주 서 (고정구)
A3: 발주일자 : | C3: ='1.발주접수'!$C$6 -> 46058 | F3: 납품요청일 : | G3: ='1.발주접수'!$C$7 -> 46072
A4: 발 주 처 | C4: 탑디뉴스 | F4: 수 신 처 | G4: 필립산업㈜
A5: TEL | C5: 010-9308-5358 | F5: TEL | G5: 031-592-6960
A6: FAX | C6: 031-8056-9544 | F6: FAX | G6: 031-592-0953
A7: E-mail | C7: topdi@topdignus.co.kr | F7: E-mail | G7: pl3077@naver.com
A8: 필수기재사항 | B8: 현 장 명 | C8: ='1.발주접수'!$C$8 -> 현장명 예시
B9: 현장주소 | C9: ='1.발주접수'!$C$10 -> 주소 예시
B10: 담당자 | C10: ='1.발주접수'!$C$11 -> 인수자 예시 | F10: 연락처 | G10: ='1.발주접수'!$C$12 -> 연락처 예시
A12: 품 명 | D12: 배관 | E12: 슬리브 | F12: 단위 | G12: 수량 | H12: 비 고
A13: ='2.고정구단가산출'!F13 -> 내화채움구조(벽체,강관용) | D13: =IFERROR(LEFT('2.고정구단가산출'!G13, FIND("*", '2.고정구단가산출'!G13) - 1), '2.고정구단가산출'!G13) -> 15 | E13: =IFERROR(RIGHT('2.고정구단가산출'!G13, LEN('2.고정구단가산출'!G13) - FIND("*", '2.고정구단가산출'!G13)), '2.고정구단가산출'!G13) -> 25 | F13: ='2.고정구단가산출'!H13 -> 개소 | G13: ='2.고정구단가산출'!I13 -> 3 | H13: ='2.고정구단가산출'!J13 -> 0
A33: 합 계 | F33: =SUM(F13:F32) -> 0 | G33: =SUM(G13:G32) -> 3
